Workbook

Sheet Summary
A1: NCO-2004 to exposure: DGE concordance vs ILO correspondence table
A3: Setting
A4: Agreement threshold (absolute difference in exposure score) | B4: 0.05 | C4: Edit this cell. Groups whose two scores differ by more than this are marked "Check".
A6: Coverage
A7: NCO-2004 groups in either source | B7: =COUNTA(Comparison!A2:A120) -> 119
A8: Groups scored via DGE concordance | B8: =COUNT(Comparison!J2:J120) -> 111
A9: Groups scored via ILO table | B9: =COUNT(Comparison!K2:K120) -> 115
A10: Groups scored by both | B10: =COUNT(Comparison!L2:L120) -> 108
A11: Groups only in DGE | B11: =COUNTIF(Comparison!N2:N120,"DGE only") -> 3
A12: Groups only in ILO table | B12: =COUNTIF(Comparison!N2:N120,"ILO only") -> 7
A13: Agreement (groups scored by both)
A14: Correlation of the two scores | B14: =CORREL(Comparison!J2:J120,Comparison!K2:K120) -> 0.93515529
A15: Mean absolute difference | B15: =AVERAGE(Comparison!M2:M120) -> 0.02732474
A16: Largest absolute difference | B16: =MAX(Comparison!M2:M120) -> 0.22
A17: Groups that agree (within threshold) | B17: =COUNTIF(Comparison!N2:N120,"Agree") -> 89
A18: Groups to check (beyond threshold) | B18: =COUNTIF(Comparison!N2:N120,"Check") -> 19
A19: Share that agree | B19: =IFERROR(B17/B9,0) -> 0.77391304
A20: Code numbering
A21: DGE occupations with an NCO-2004 code | B21: =COUNTIF('DGE links'!F2:F3451,"?*") -> 2688
A22: ...of which keep the same 3-digit number in NCO-2015 | B22: =COUNTIF('DGE links'!G2:G3451,"Yes") -> 581
A23: Share keeping the same 3-digit number | B23: =IFERROR(B22/B21,0) -> 0.21614583
A25: How to read this workbook
A26: Comparison: one row per NCO-2004 group. "Exposure: DGE route" averages the NCO-2015 group scores of the occupations DGE lists under that old group (each old occupation counts once). "Exposure: ILO route" averages the ILO scores of the ISCO-08 jobs the ILO table links to that ISCO-88 group.
A27: DGE links: India's own concordance, one row per occupation and NCO-2004 code. ILO links: the ILO ISCO-08 to ISCO-88 table, one row per link.
A28: Why both: NCO-2004 is based on ISCO-88 but departs from it in places (e.g. farm labourers are 920 in NCO-2004 and 921 in ISCO-88; general managers are 130). "DGE only" and "ILO only" rows are often these renumbered groups.
A29: Colour key: blue = input values from the sources; green = formulas pulling from another sheet; yellow = setting you can change.

Sheet Comparison
A1: NCO-2004 group | B1: Main NCO-2015 group (DGE) | C1: Main NCO-2015 group title | D1: NCO-2015 groups reached via DGE | E1: ISCO-08 groups reached via ILO table | F1: Groups reached by both | G1: Overlap (shared / all groups reached) | H1: DGE occupations | I1: ISCO-08 jobs linked | J1: Exposure: DGE route | K1: Exposure: ILO route | L1: Difference (DGE - ILO) | M1: Absolute difference | N1: Agreement | O1: Score used in dataset | P1: Source of score used
A2: 011 | E2: 011 021 031 | H2: =SUMPRODUCT(('DGE links'!$F$2:$F$3451=A2)*1) -> 0 | I2: =SUMPRODUCT(('ILO links'!$G$2:$G$674=A2)*'ILO links'!$J$2:$J$674) -> 3 | J2: =IFERROR(SUMPRODUCT(('DGE links'!$F$2:$F$3451=A2)*'DGE links'!$H$2:$H$3451*'DGE links'!$I$2:$I$3451*'DGE links'!$J$2:$J$3451)/SUMPRODUCT(('DGE links'!$F$2:$F$3451=A2)*'DGE links'!$H$2:$H$3451*'DGE links'!$J$2:$J$3451),"") | K2: =IFERROR(AVERAGEIFS('ILO links'!$H$2:$H$674,'ILO links'!$G$2:$G$674,A2,'ILO links'!$J$2:$J$674,1),"") | L2: =IF(AND(ISNUMBER(J2),ISNUMBER(K2)),J2-K2,"") | M2: =IF(ISNUMBER(L2),ABS(L2),"") | N2: =IF(ISNUMBER(M2),IF(M2<=Summary!$B$4,"Agree","Check"),IF(ISNUMBER(J2),"DGE only",IF(ISNUMBER(K2),"ILO only","Not scored"))) -> Not scored | O2: =IF(ISNUMBER(J2),J2,IF(ISNUMBER(K2),K2,"")) | P2: =IF(ISNUMBER(J2),"DGE",IF(ISNUMBER(K2),"ILO table",""))
A3: 111 | B3: 111 | C3: Legislators and senior officials | D3: 111 | E3: 111 | F3: 111 | G3: 1 | H3: =SUMPRODUCT(('DGE links'!$F$2:$F$3451=A3)*1) -> 4 | I3: =SUMPRODUCT(('ILO links'!$G$2:$G$674=A3)*'ILO links'!$J$2:$J$674) -> 1 | J3: =IFERROR(SUMPRODUCT(('DGE links'!$F$2:$F$3451=A3)*'DGE links'!$H$2:$H$3451*'DGE links'!$I$2:$I$3451*'DGE links'!$J$2:$J$3451)/SUMPRODUCT(('DGE links'!$F$2:$F$3451=A3)*'DGE links'!$H$2:$H$3451*'DGE links'!$J$2:$J$3451),"") -> 0.3225 | K3: =IFERROR(AVERAGEIFS('ILO links'!$H$2:$H$674,'ILO links'!$G$2:$G$674,A3,'ILO links'!$J$2:$J$674,1),"") -> 0.31 | L3: =IF(AND(ISNUMBER(J3),ISNUMBER(K3)),J3-K3,"") -> 0.0125 | M3: =IF(ISNUMBER(L3),ABS(L3),"") -> 0.0125 | N3: =IF(ISNUMBER(M3),IF(M3<=Summary!$B$4,"Agree","Check"),IF(ISNUMBER(J3),"DGE only",IF(ISNUMBER(K3),"ILO only","Not scored"))) -> Agree | O3: =IF(ISNUMBER(J3),J3,IF(ISNUMBER(K3),K3,"")) -> 0.3225 | P3: =IF(ISNUMBER(J3),"DGE",IF(ISNUMBER(K3),"ILO table","")) -> DGE
A4: 112 | B4: 111 | C4: Legislators and senior officials | D4: 111 | E4: 111 | F4: 111 | G4: 1 | H4: =SUMPRODUCT(('DGE links'!$F$2:$F$3451=A4)*1) -> 9 | I4: =SUMPRODUCT(('ILO links'!$G$2:$G$674=A4)*'ILO links'!$J$2:$J$674) -> 1 | J4: =IFERROR(SUMPRODUCT(('DGE links'!$F$2:$F$3451=A4)*'DGE links'!$H$2:$H$3451*'DGE links'!$I$2:$I$3451*'DGE links'!$J$2:$J$3451)/SUMPRODUCT(('DGE links'!$F$2:$F$3451=A4)*'DGE links'!$H$2:$H$3451*'DGE links'!$J$2:$J$3451),"") -> 0.3225 | K4: =IFERROR(AVERAGEIFS('ILO links'!$H$2:$H$674,'ILO links'!$G$2:$G$674,A4,'ILO links'!$J$2:$J$674,1),"") -> 0.38 | L4: =IF(AND(ISNUMBER(J4),ISNUMBER(K4)),J4-K4,"") -> -0.0575 | M4: =IF(ISNUMBER(L4),ABS(L4),"") -> 0.0575 | N4: =IF(ISNUMBER(M4),IF(M4<=Summary!$B$4,"Agree","Check"),IF(ISNUMBER(J4),"DGE only",IF(ISNUMBER(K4),"ILO only","Not scored"))) -> Check | O4: =IF(ISNUMBER(J4),J4,IF(ISNUMBER(K4),K4,"")) -> 0.3225 | P4: =IF(ISNUMBER(J4),"DGE",IF(ISNUMBER(K4),"ILO table","")) -> DGE
A5: 113 | E5: 111 | H5: =SUMPRODUCT(('DGE links'!$F$2:$F$3451=A5)*1) -> 0 | I5: =SUMPRODUCT(('ILO links'!$G$2:$G$674=A5)*'ILO links'!$J$2:$J$674) -> 1 | J5: =IFERROR(SUMPRODUCT(('DGE links'!$F$2:$F$3451=A5)*'DGE links'!$H$2:$H$3451*'DGE links'!$I$2:$I$3451*'DGE links'!$J$2:$J$3451)/SUMPRODUCT(('DGE links'!$F$2:$F$3451=A5)*'DGE links'!$H$2:$H$3451*'DGE links'!$J$2:$J$3451),"") | K5: =IFERROR(AVERAGEIFS('ILO links'!$H$2:$H$674,'ILO links'!$G$2:$G$674,A5,'ILO links'!$J$2:$J$674,1),"") -> 0.23 | L5: =IF(AND(ISNUMBER(J5),ISNUMBER(K5)),J5-K5,"") | M5: =IF(ISNUMBER(L5),ABS(L5),"") | N5: =IF(ISNUMBER(M5),IF(M5<=Summary!$B$4,"Agree","Check"),IF(ISNUMBER(J5),"DGE only",IF(ISNUMBER(K5),"ILO only","Not scored"))) -> ILO only | O5: =IF(ISNUMBER(J5),J5,IF(ISNUMBER(K5),K5,"")) -> 0.23 | P5: =IF(ISNUMBER(J5),"DGE",IF(ISNUMBER(K5),"ILO table","")) -> ILO table
A6: 114 | B6: 111 | C6: Legislators and senior officials | D6: 111 | E6: 111 | F6: 111 | G6: 1 | H6: =SUMPRODUCT(('DGE links'!$F$2:$F$3451=A6)*1) -> 4 | I6: =SUMPRODUCT(('ILO links'!$G$2:$G$674=A6)*'ILO links'!$J$2:$J$674) -> 1 | J6: =IFERROR(SUMPRODUCT(('DGE links'!$F$2:$F$3451=A6)*'DGE links'!$H$2:$H$3451*'DGE links'!$I$2:$I$3451*'DGE links'!$J$2:$J$3451)/SUMPRODUCT(('DGE links'!$F$2:$F$3451=A6)*'DGE links'!$H$2:$H$3451*'DGE links'!$J$2:$J$3451),"") -> 0.3225 | K6: =IFERROR(AVERAGEIFS('ILO links'!$H$2:$H$674,'ILO links'!$G$2:$G$674,A6,'ILO links'!$J$2:$J$674,1),"") -> 0.37 | L6: =IF(AND(ISNUMBER(J6),ISNUMBER(K6)),J6-K6,"") -> -0.0475 | M6: =IF(ISNUMBER(L6),ABS(L6),"") -> 0.0475 | N6: =IF(ISNUMBER(M6),IF(M6<=Summary!$B$4,"Agree","Check"),IF(ISNUMBER(J6),"DGE only",IF(ISNUMBER(K6),"ILO only","Not scored"))) -> Agree | O6: =IF(ISNUMBER(J6),J6,IF(ISNUMBER(K6),K6,"")) -> 0.3225 | P6: =IF(ISNUMBER(J6),"DGE",IF(ISNUMBER(K6),"ILO table","")) -> DGE
A7: 121 | B7: 112 | C7: Managing directors and chief executives | D7: 112 | E7: 112 | F7: 112 | G7: 1 | H7: =SUMPRODUCT(('DGE links'!$F$2:$F$3451=A7)*1) -> 40 | I7: =SUMPRODUCT(('ILO links'!$G$2:$G$674=A7)*'ILO links'!$J$2:$J$674) -> 1 | J7: =IFERROR(SUMPRODUCT(('DGE links'!$F$2:$F$3451=A7)*'DGE links'!$H$2:$H$3451*'DGE links'!$I$2:$I$3451*'DGE links'!$J$2:$J$3451)/SUMPRODUCT(('DGE links'!$F$2:$F$3451=A7)*'DGE links'!$H$2:$H$3451*'DGE links'!$J$2:$J$3451),"") -> 0.38 | K7: =IFERROR(AVERAGEIFS('ILO links'!$H$2:$H$674,'ILO links'!$G$2:$G$674,A7,'ILO links'!$J$2:$J$674,1),"") -> 0.38 | L7: =IF(AND(ISNUMBER(J7),ISNUMBER(K7)),J7-K7,"") -> 0 | M7: =IF(ISNUMBER(L7),ABS(L7),"") -> 0 | N7: =IF(ISNUMBER(M7),IF(M7<=Summary!$B$4,"Agree","Check"),IF(ISNUMBER(J7),"DGE only",IF(ISNUMBER(K7),"ILO only","Not scored"))) -> Agree | O7: =IF(ISNUMBER(J7),J7,IF(ISNUMBER(K7),K7,"")) -> 0.38 | P7: =IF(ISNUMBER(J7),"DGE",IF(ISNUMBER(K7),"ILO table","")) -> DGE
A8: 122 | B8: 132 | C8: Manufacturing, mining, construction, and distribution managers | D8: 121 131 132 133 134 141 142 265 | E8: 121 131 132 133 134 141 142 143 265 312 | F8: 121 131 132 133 134 141 142 265 | G8: 0.8 | H8: =SUMPRODUCT(('DGE links'!$F$2:$F$3451=A8)*1) -> 61 | I8: =SUMPRODUCT(('ILO links'!$G$2:$G$674=A8)*'ILO links'!$J$2:$J$674) -> 22 | J8: =IFERROR(SUMPRODUCT(('DGE links'!$F$2:$F$3451=A8)*'DGE links'!$H$2:$H$3451*'DGE links'!$I$2:$I$3451*'DGE links'!$J$2:$J$3451)/SUMPRODUCT(('DGE links'!$F$2:$F$3451=A8)*'DGE links'!$H$2:$H$3451*'DGE links'!$J$2:$J$3451),"") -> 0.34646557 | K8: =IFERROR(AVERAGEIFS('ILO links'!$H$2:$H$674,'ILO links'!$G$2:$G$674,A8,'ILO links'!$J$2:$J$674,1),"") -> 0.36 | L8: =IF(AND(ISNUMBER(J8),ISNUMBER(K8)),J8-K8,"") -> -0.013534426 | M8: =IF(ISNUMBER(L8),ABS(L8),"") -> 0.013534426 | N8: =IF(ISNUMBER(M8),IF(M8<=Summary!$B$4,"Agree","Check"),IF(ISNUMBER(J8),"DGE only",IF(ISNUMBER(K8),"ILO only","Not scored"))) -> Agree | O8: =IF(ISNUMBER(J8),J8,IF(ISNUMBER(K8),K8,"")) -> 0.34646557 | P8: =IF(ISNUMBER(J8),"DGE",IF(ISNUMBER(K8),"ILO table","")) -> DGE
A9: 123 | B9: 121 | C9: Business services and administration managers | D9: 121 122 132 | E9: 121 122 132 133 | F9: 121 122 132 | G9: 0.75 | H9: =SUMPRODUCT(('DGE links'!$F$2:$F$3451=A9)*1) -> 14 | I9: =SUMPRODUCT(('ILO links'!$G$2:$G$674=A9)*'ILO links'!$J$2:$J$674) -> 9 | J9: =IFERROR(SUMPRODUCT(('DGE links'!$F$2:$F$3451=A9)*'DGE links'!$H$2:$H$3451*'DGE links'!$I$2:$I$3451*'DGE links'!$J$2:$J$3451)/SUMPRODUCT(('DGE links'!$F$2:$F$3451=A9)*'DGE links'!$H$2:$H$3451*'DGE links'!$J$2:$J$3451),"") -> 0.38607143 | K9: =IFERROR(AVERAGEIFS('ILO links'!$H$2:$H$674,'ILO links'!$G$2:$G$674,A9,'ILO links'!$J$2:$J$674,1),"") -> 0.39222222 | L9: =IF(AND(ISNUMBER(J9),ISNUMBER(K9)),J9-K9,"") -> -0.0061507937 | M9: =IF(ISNUMBER(L9),ABS(L9),"") -> 0.0061507937 | N9: =IF(ISNUMBER(M9),IF(M9<=Summary!$B$4,"Agree","Check"),IF(ISNUMBER(J9),"DGE only",IF(ISNUMBER(K9),"ILO only","Not scored"))) -> Agree | O9: =IF(ISNUMBER(J9),J9,IF(ISNUMBER(K9),K9,"")) -> 0.38607143 | P9: =IF(ISNUMBER(J9),"DGE",IF(ISNUMBER(K9),"ILO table","")) -> DGE
A10: 130 | B10: 132 | C10: Manufacturing, mining, construction, and distribution managers | D10: 121 131 132 133 141 142 143 | H10: =SUMPRODUCT(('DGE links'!$F$2:$F$3451=A10)*1) -> 28 | I10: =SUMPRODUCT(('ILO links'!$G$2:$G$674=A10)*'ILO links'!$J$2:$J$674) -> 0 | J10: =IFERROR(SUMPRODUCT(('DGE links'!$F$2:$F$3451=A10)*'DGE links'!$H$2:$H$3451*'DGE links'!$I$2:$I$3451*'DGE links'!$J$2:$J$3451)/SUMPRODUCT(('DGE links'!$F$2:$F$3451=A10)*'DGE links'!$H$2:$H$3451*'DGE links'!$J$2:$J$3451),"") -> 0.34660714 | K10: =IFERROR(AVERAGEIFS('ILO links'!$H$2:$H$674,'ILO links'!$G$2:$G$674,A10,'ILO links'!$J$2:$J$674,1),"") | L10: =IF(AND(ISNUMBER(J10),ISNUMBER(K10)),J10-K10,"") | M10: =IF(ISNUMBER(L10),ABS(L10),"") | N10: =IF(ISNUMBER(M10),IF(M10<=Summary!$B$4,"Agree","Check"),IF(ISNUMBER(J10),"DGE only",IF(ISNUMBER(K10),"ILO only","Not scored"))) -> DGE only | O10: =IF(ISNUMBER(J10),J10,IF(ISNUMBER(K10),K10,"")) -> 0.34660714 | P10: =IF(ISNUMBER(J10),"DGE",IF(ISNUMBER(K10),"ILO table","")) -> DGE
A11: 131 | E11: 121 122 132 133 134 141 142 143 522 611 612 613 | H11: =SUMPRODUCT(('DGE links'!$F$2:$F$3451=A11)*1) -> 0 | I11: =SUMPRODUCT(('ILO links'!$G$2:$G$674=A11)*'ILO links'!$J$2:$J$674) -> 31 | J11: =IFERROR(SUMPRODUCT(('DGE links'!$F$2:$F$3451=A11)*'DGE links'!$H$2:$H$3451*'DGE links'!$I$2:$I$3451*'DGE links'!$J$2:$J$3451)/SUMPRODUCT(('DGE links'!$F$2:$F$3451=A11)*'DGE links'!$H$2:$H$3451*'DGE links'!$J$2:$J$3451),"") | K11: =IFERROR(AVERAGEIFS('ILO links'!$H$2:$H$674,'ILO links'!$G$2:$G$674,A11,'ILO links'!$J$2:$J$674,1),"") -> 0.333 | L11: =IF(AND(ISNUMBER(J11),ISNUMBER(K11)),J11-K11,"") | M11: =IF(ISNUMBER(L11),ABS(L11),"") | N11: =IF(ISNUMBER(M11),IF(M11<=Summary!$B$4,"Agree","Check"),IF(ISNUMBER(J11),"DGE only",IF(ISNUMBER(K11),"ILO only","Not scored"))) -> ILO only | O11: =IF(ISNUMBER(J11),J11,IF(ISNUMBER(K11),K11,"")) -> 0.333 | P11: =IF(ISNUMBER(J11),"DGE",IF(ISNUMBER(K11),"ILO table","")) -> ILO table
A12: 211 | B12: 211 | C12: Physical and earth science professionals | D12: 211 226 | E12: 211 226 | F12: 211 226 | G12: 1 | H12: =SUMPRODUCT(('DGE links'!$F$2:$F$3451=A12)*1) -> 34 | I12: =SUMPRODUCT(('ILO links'!$G$2:$G$674=A12)*'ILO links'!$J$2:$J$674) -> 5 | J12: =IFERROR(SUMPRODUCT(('DGE links'!$F$2:$F$3451=A12)*'DGE links'!$H$2:$H$3451*'DGE links'!$I$2:$I$3451*'DGE links'!$J$2:$J$3451)/SUMPRODUCT(('DGE links'!$F$2:$F$3451=A12)*'DGE links'!$H$2:$H$3451*'DGE links'!$J$2:$J$3451),"") -> 0.41291515 | K12: =IFERROR(AVERAGEIFS('ILO links'!$H$2:$H$674,'ILO links'!$G$2:$G$674,A12,'ILO links'!$J$2:$J$674,1),"") -> 0.4 | L12: =IF(AND(ISNUMBER(J12),ISNUMBER(K12)),J12-K12,"") -> 0.012915152 | M12: =IF(ISNUMBER(L12),ABS(L12),"") -> 0.012915152 | N12: =IF(ISNUMBER(M12),IF(M12<=Summary!$B$4,"Agree","Check"),IF(ISNUMBER(J12),"DGE only",IF(ISNUMBER(K12),"ILO only","Not scored"))) -> Agree | O12: =IF(ISNUMBER(J12),J12,IF(ISNUMBER(K12),K12,"")) -> 0.41291515 | P12: =IF(ISNUMBER(J12),"DGE",IF(ISNUMBER(K12),"ILO table","")) -> DGE
A13: 212 | B13: 212 | C13: Mathematicians, actuaries and statisticians | D13: 212 | E13: 212 | F13: 212 | G13: 1 | H13: =SUMPRODUCT(('DGE links'!$F$2:$F$3451=A13)*1) -> 6 | I13: =SUMPRODUCT(('ILO links'!$G$2:$G$674=A13)*'ILO links'!$J$2:$J$674) -> 1 | J13: =IFERROR(SUMPRODUCT(('DGE links'!$F$2:$F$3451=A13)*'DGE links'!$H$2:$H$3451*'DGE links'!$I$2:$I$3451*'DGE links'!$J$2:$J$3451)/SUMPRODUCT(('DGE links'!$F$2:$F$3451=A13)*'DGE links'!$H$2:$H$3451*'DGE links'!$J$2:$J$3451),"") -> 0.56 | K13: =IFERROR(AVERAGEIFS('ILO links'!$H$2:$H$674,'ILO links'!$G$2:$G$674,A13,'ILO links'!$J$2:$J$674,1),"") -> 0.56 | L13: =IF(AND(ISNUMBER(J13),ISNUMBER(K13)),J13-K13,"") -> 0 | M13: =IF(ISNUMBER(L13),ABS(L13),"") -> 0 | N13: =IF(ISNUMBER(M13),IF(M13<=Summary!$B$4,"Agree","Check"),IF(ISNUMBER(J13),"DGE only",IF(ISNUMBER(K13),"ILO only","Not scored"))) -> Agree | O13: =IF(ISNUMBER(J13),J13,IF(ISNUMBER(K13),K13,"")) -> 0.56 | P13: =IF(ISNUMBER(J13),"DGE",IF(ISNUMBER(K13),"ILO table","")) -> DGE
A14: 213 | B14: 251 | C14: Software and applications developers and analysts | D14: 251 252 | E14: 251 252 351 | F14: 251 252 | G14: 0.66666667 | H14: =SUMPRODUCT(('DGE links'!$F$2:$F$3451=A14)*1) -> 15 | I14: =SUMPRODUCT(('ILO links'!$G$2:$G$674=A14)*'ILO links'!$J$2:$J$674) -> 10 | J14: =IFERROR(SUMPRODUCT(('DGE links'!$F$2:$F$3451=A14)*'DGE links'!$H$2:$H$3451*'DGE links'!$I$2:$I$3451*'DGE links'!$J$2:$J$3451)/SUMPRODUCT(('DGE links'!$F$2:$F$3451=A14)*'DGE links'!$H$2:$H$3451*'DGE links'!$J$2:$J$3451),"") -> 0.54425 | K14: =IFERROR(AVERAGEIFS('ILO links'!$H$2:$H$674,'ILO links'!$G$2:$G$674,A14,'ILO links'!$J$2:$J$674,1),"") -> 0.532 | L14: =IF(AND(ISNUMBER(J14),ISNUMBER(K14)),J14-K14,"") -> 0.01225 | M14: =IF(ISNUMBER(L14),ABS(L14),"") -> 0.01225 | N14: =IF(ISNUMBER(M14),IF(M14<=Summary!$B$4,"Agree","Check"),IF(ISNUMBER(J14),"DGE only",IF(ISNUMBER(K14),"ILO only","Not scored"))) -> Agree | O14: =IF(ISNUMBER(J14),J14,IF(ISNUMBER(K14),K14,"")) -> 0.54425 | P14: =IF(ISNUMBER(J14),"DGE",IF(ISNUMBER(K14),"ILO table","")) -> DGE
A15: 214 | B15: 214 | C15: Engineering professionals (excluding electrotechnology) | D15: 214 215 216 | E15: 214 215 216 | F15: 214 215 216 | G15: 1 | H15: =SUMPRODUCT(('DGE links'!$F$2:$F$3451=A15)*1) -> 102 | I15: =SUMPRODUCT(('ILO links'!$G$2:$G$674=A15)*'ILO links'!$J$2:$J$674) -> 14 | J15: =IFERROR(SUMPRODUCT(('DGE links'!$F$2:$F$3451=A15)*'DGE links'!$H$2:$H$3451*'DGE links'!$I$2:$I$3451*'DGE links'!$J$2:$J$3451)/SUMPRODUCT(('DGE links'!$F$2:$F$3451=A15)*'DGE links'!$H$2:$H$3451*'DGE links'!$J$2:$J$3451),"") -> 0.34814902 | K15: =IFERROR(AVERAGEIFS('ILO links'!$H$2:$H$674,'ILO links'!$G$2:$G$674,A15,'ILO links'!$J$2:$J$674,1),"") -> 0.365 | L15: =IF(AND(ISNUMBER(J15),ISNUMBER(K15)),J15-K15,"") -> -0.01685098 | M15: =IF(ISNUMBER(L15),ABS(L15),"") -> 0.01685098 | N15: =IF(ISNUMBER(M15),IF(M15<=Summary!$B$4,"Agree","Check"),IF(ISNUMBER(J15),"DGE only",IF(ISNUMBER(K15),"ILO only","Not scored"))) -> Agree | O15: =IF(ISNUMBER(J15),J15,IF(ISNUMBER(K15),K15,"")) -> 0.34814902 | P15: =IF(ISNUMBER(J15),"DGE",IF(ISNUMBER(K15),"ILO table","")) -> DGE
A16: 221 | B16: 213 | C16: Life science professionals | D16: 213 221 225 | E16: 213 221 225 | F16: 213 221 225 | G16: 1 | H16: =SUMPRODUCT(('DGE links'!$F$2:$F$3451=A16)*1) -> 38 | I16: =SUMPRODUCT(('ILO links'!$G$2:$G$674=A16)*'ILO links'!$J$2:$J$674) -> 5 | J16: =IFERROR(SUMPRODUCT(('DGE links'!$F$2:$F$3451=A16)*'DGE links'!$H$2:$H$3451*'DGE links'!$I$2:$I$3451*'DGE links'!$J$2:$J$3451)/SUMPRODUCT(('DGE links'!$F$2:$F$3451=A16)*'DGE links'!$H$2:$H$3451*'DGE links'!$J$2:$J$3451),"") -> 0.33840541 | K16: =IFERROR(AVERAGEIFS('ILO links'!$H$2:$H$674,'ILO links'!$G$2:$G$674,A16,'ILO links'!$J$2:$J$674,1),"") -> 0.296 | L16: =IF(AND(ISNUMBER(J16),ISNUMBER(K16)),J16-K16,"") -> 0.042405405 | M16: =IF(ISNUMBER(L16),ABS(L16),"") -> 0.042405405 | N16: =IF(ISNUMBER(M16),IF(M16<=Summary!$B$4,"Agree","Check"),IF(ISNUMBER(J16),"DGE only",IF(ISNUMBER(K16),"ILO only","Not scored"))) -> Agree | O16: =IF(ISNUMBER(J16),J16,IF(ISNUMBER(K16),K16,"")) -> 0.33840541 | P16: =IF(ISNUMBER(J16),"DGE",IF(ISNUMBER(K16),"ILO table","")) -> DGE
A17: 222 | B17: 221 | C17: Medical doctors | D17: 221 223 225 226 | E17: 221 225 226 | F17: 221 225 226 | G17: 0.75 | H17: =SUMPRODUCT(('DGE links'!$F$2:$F$3451=A17)*1) -> 43 | I17: =SUMPRODUCT(('ILO links'!$G$2:$G$674=A17)*'ILO links'!$J$2:$J$674) -> 7 | J17: =IFERROR(SUMPRODUCT(('DGE links'!$F$2:$F$3451=A17)*'DGE links'!$H$2:$H$3451*'DGE links'!$I$2:$I$3451*'DGE links'!$J$2:$J$3451)/SUMPRODUCT(('DGE links'!$F$2:$F$3451=A17)*'DGE links'!$H$2:$H$3451*'DGE links'!$J$2:$J$3451),"") -> 0.26001395 | K17: =IFERROR(AVERAGEIFS('ILO links'!$H$2:$H$674,'ILO links'!$G$2:$G$674,A17,'ILO links'!$J$2:$J$674,1),"") -> 0.23714286 | L17: =IF(AND(ISNUMBER(J17),ISNUMBER(K17)),J17-K17,"") -> 0.022871096 | M17: =IF(ISNUMBER(L17),ABS(L17),"") -> 0.022871096 | N17: =IF(ISNUMBER(M17),IF(M17<=Summary!$B$4,"Agree","Check"),IF(ISNUMBER(J17),"DGE only",IF(ISNUMBER(K17),"ILO only","Not scored"))) -> Agree | O17: =IF(ISNUMBER(J17),J17,IF(ISNUMBER(K17),K17,"")) -> 0.26001395 | P17: =IF(ISNUMBER(J17),"DGE",IF(ISNUMBER(K17),"ILO table","")) -> DGE
A18: 223 | B18: 222 | C18: Nursing and midwifery professionals | D18: 222 | E18: 134 222 322 | F18: 222 | G18: 0.33333333 | H18: =SUMPRODUCT(('DGE links'!$F$2:$F$3451=A18)*1) -> 2 | I18: =SUMPRODUCT(('ILO links'!$G$2:$G$674=A18)*'ILO links'!$J$2:$J$674) -> 6 | J18: =IFERROR(SUMPRODUCT(('DGE links'!$F$2:$F$3451=A18)*'DGE links'!$H$2:$H$3451*'DGE links'!$I$2:$I$3451*'DGE links'!$J$2:$J$3451)/SUMPRODUCT(('DGE links'!$F$2:$F$3451=A18)*'DGE links'!$H$2:$H$3451*'DGE links'!$J$2:$J$3451),"") -> 0.275 | K18: =IFERROR(AVERAGEIFS('ILO links'!$H$2:$H$674,'ILO links'!$G$2:$G$674,A18,'ILO links'!$J$2:$J$674,1),"") -> 0.27833333 | L18: =IF(AND(ISNUMBER(J18),ISNUMBER(K18)),J18-K18,"") -> -0.0033333333 | M18: =IF(ISNUMBER(L18),ABS(L18),"") -> 0.0033333333 | N18: =IF(ISNUMBER(M18),IF(M18<=Summary!$B$4,"Agree","Check"),IF(ISNUMBER(J18),"DGE only",IF(ISNUMBER(K18),"ILO only","Not scored"))) -> Agree | O18: =IF(ISNUMBER(J18),J18,IF(ISNUMBER(K18),K18,"")) -> 0.275 | P18: =IF(ISNUMBER(J18),"DGE",IF(ISNUMBER(K18),"ILO table","")) -> DGE
A19: 231 | B19: 231 | C19: University and higher education teachers | D19: 231 | E19: 231 232 | F19: 231 | G19: 0.5 | H19: =SUMPRODUCT(('DGE links'!$F$2:$F$3451=A19)*1) -> 13 | I19: =SUMPRODUCT(('ILO links'!$G$2:$G$674=A19)*'ILO links'!$J$2:$J$674) -> 2 | J19: =IFERROR(SUMPRODUCT(('DGE links'!$F$2:$F$3451=A19)*'DGE links'!$H$2:$H$3451*'DGE links'!$I$2:$I$3451*'DGE links'!$J$2:$J$3451)/SUMPRODUCT(('DGE links'!$F$2:$F$3451=A19)*'DGE links'!$H$2:$H$3451*'DGE links'!$J$2:$J$3451),"") -> 0.37 | K19: =IFERROR(AVERAGEIFS('ILO links'!$H$2:$H$674,'ILO links'!$G$2:$G$674,A19,'ILO links'!$J$2:$J$674,1),"") -> 0.36 | L19: =IF(AND(ISNUMBER(J19),ISNUMBER(K19)),J19-K19,"") -> 0.01 | M19: =IF(ISNUMBER(L19),ABS(L19),"") -> 0.01 | N19: =IF(ISNUMBER(M19),IF(M19<=Summary!$B$4,"Agree","Check"),IF(ISNUMBER(J19),"DGE only",IF(ISNUMBER(K19),"ILO only","Not scored"))) -> Agree | O19: =IF(ISNUMBER(J19),J19,IF(ISNUMBER(K19),K19,"")) -> 0.37 | P19: =IF(ISNUMBER(J19),"DGE",IF(ISNUMBER(K19),"ILO table","")) -> DGE
A20: 232 | B20: 233 | C20: Secondary education teachers | D20: 233 | E20: 232 233 | F20: 233 | G20: 0.5 | H20: =SUMPRODUCT(('DGE links'!$F$2:$F$3451=A20)*1) -> 5 | I20: =SUMPRODUCT(('ILO links'!$G$2:$G$674=A20)*'ILO links'!$J$2:$J$674) -> 2 | J20: =IFERROR(SUMPRODUCT(('DGE links'!$F$2:$F$3451=A20)*'DGE links'!$H$2:$H$3451*'DGE links'!$I$2:$I$3451*'DGE links'!$J$2:$J$3451)/SUMPRODUCT(('DGE links'!$F$2:$F$3451=A20)*'DGE links'!$H$2:$H$3451*'DGE links'!$J$2:$J$3451),"") -> 0.3 | K20: =IFERROR(AVERAGEIFS('ILO links'!$H$2:$H$674,'ILO links'!$G$2:$G$674,A20,'ILO links'!$J$2:$J$674,1),"") -> 0.325 | L20: =IF(AND(ISNUMBER(J20),ISNUMBER(K20)),J20-K20,"") -> -0.025 | M20: =IF(ISNUMBER(L20),ABS(L20),"") -> 0.025 | N20: =IF(ISNUMBER(M20),IF(M20<=Summary!$B$4,"Agree","Check"),IF(ISNUMBER(J20),"DGE only",IF(ISNUMBER(K20),"ILO only","Not scored"))) -> Agree | O20: =IF(ISNUMBER(J20),J20,IF(ISNUMBER(K20),K20,"")) -> 0.3 | P20: =IF(ISNUMBER(J20),"DGE",IF(ISNUMBER(K20),"ILO table","")) -> DGE
A21: 233 | B21: 235 | C21: Other teaching professionals | D21: 235 | E21: 234 | G21: 0 | H21: =SUMPRODUCT(('DGE links'!$F$2:$F$3451=A21)*1) -> 4 | I21: =SUMPRODUCT(('ILO links'!$G$2:$G$674=A21)*'ILO links'!$J$2:$J$674) -> 2 | J21: =IFERROR(SUMPRODUCT(('DGE links'!$F$2:$F$3451=A21)*'DGE links'!$H$2:$H$3451*'DGE links'!$I$2:$I$3451*'DGE links'!$J$2:$J$3451)/SUMPRODUCT(('DGE links'!$F$2:$F$3451=A21)*'DGE links'!$H$2:$H$3451*'DGE links'!$J$2:$J$3451),"") -> 0.3586 | K21: =IFERROR(AVERAGEIFS('ILO links'!$H$2:$H$674,'ILO links'!$G$2:$G$674,A21,'ILO links'!$J$2:$J$674,1),"") -> 0.235 | L21: =IF(AND(ISNUMBER(J21),ISNUMBER(K21)),J21-K21,"") -> 0.1236 | M21: =IF(ISNUMBER(L21),ABS(L21),"") -> 0.1236 | N21: =IF(ISNUMBER(M21),IF(M21<=Summary!$B$4,"Agree","Check"),IF(ISNUMBER(J21),"DGE only",IF(ISNUMBER(K21),"ILO only","Not scored"))) -> Check | O21: =IF(ISNUMBER(J21),J21,IF(ISNUMBER(K21),K21,"")) -> 0.3586 | P21: =IF(ISNUMBER(J21),"DGE",IF(ISNUMBER(K21),"ILO table","")) -> DGE
A22: 234 | E22: 235 | H22: =SUMPRODUCT(('DGE links'!$F$2:$F$3451=A22)*1) -> 0 | I22: =SUMPRODUCT(('ILO links'!$G$2:$G$674=A22)*'ILO links'!$J$2:$J$674) -> 1 | J22: =IFERROR(SUMPRODUCT(('DGE links'!$F$2:$F$3451=A22)*'DGE links'!$H$2:$H$3451*'DGE links'!$I$2:$I$3451*'DGE links'!$J$2:$J$3451)/SUMPRODUCT(('DGE links'!$F$2:$F$3451=A22)*'DGE links'!$H$2:$H$3451*'DGE links'!$J$2:$J$3451),"") | K22: =IFERROR(AVERAGEIFS('ILO links'!$H$2:$H$674,'ILO links'!$G$2:$G$674,A22,'ILO links'!$J$2:$J$674,1),"") -> 0.28 | L22: =IF(AND(ISNUMBER(J22),ISNUMBER(K22)),J22-K22,"") | M22: =IF(ISNUMBER(L22),ABS(L22),"") | N22: =IF(ISNUMBER(M22),IF(M22<=Summary!$B$4,"Agree","Check"),IF(ISNUMBER(J22),"DGE only",IF(ISNUMBER(K22),"ILO only","Not scored"))) -> ILO only | O22: =IF(ISNUMBER(J22),J22,IF(ISNUMBER(K22),K22,"")) -> 0.28 | P22: =IF(ISNUMBER(J22),"DGE",IF(ISNUMBER(K22),"ILO table","")) -> ILO table
A23: 235 | E23: 235 | H23: =SUMPRODUCT(('DGE links'!$F$2:$F$3451=A23)*1) -> 0 | I23: =SUMPRODUCT(('ILO links'!$G$2:$G$674=A23)*'ILO links'!$J$2:$J$674) -> 6 | J23: =IFERROR(SUMPRODUCT(('DGE links'!$F$2:$F$3451=A23)*'DGE links'!$H$2:$H$3451*'DGE links'!$I$2:$I$3451*'DGE links'!$J$2:$J$3451)/SUMPRODUCT(('DGE links'!$F$2:$F$3451=A23)*'DGE links'!$H$2:$H$3451*'DGE links'!$J$2:$J$3451),"") | K23: =IFERROR(AVERAGEIFS('ILO links'!$H$2:$H$674,'ILO links'!$G$2:$G$674,A23,'ILO links'!$J$2:$J$674,1),"") -> 0.37166667 | L23: =IF(AND(ISNUMBER(J23),ISNUMBER(K23)),J23-K23,"") | M23: =IF(ISNUMBER(L23),ABS(L23),"") | N23: =IF(ISNUMBER(M23),IF(M23<=Summary!$B$4,"Agree","Check"),IF(ISNUMBER(J23),"DGE only",IF(ISNUMBER(K23),"ILO only","Not scored"))) -> ILO only | O23: =IF(ISNUMBER(J23),J23,IF(ISNUMBER(K23),K23,"")) -> 0.37166667 | P23: =IF(ISNUMBER(J23),"DGE",IF(ISNUMBER(K23),"ILO table","")) -> ILO table
A24: 241 | B24: 241 | C24: Finance professionals | D24: 241 242 243 333 | E24: 226 241 242 243 333 | F24: 241 242 243 333 | G24: 0.8 | H24: =SUMPRODUCT(('DGE links'!$F$2:$F$3451=A24)*1) -> 21 | I24: =SUMPRODUCT(('ILO links'!$G$2:$G$674=A24)*'ILO links'!$J$2:$J$674) -> 11 | J24: =IFERROR(SUMPRODUCT(('DGE links'!$F$2:$F$3451=A24)*'DGE links'!$H$2:$H$3451*'DGE links'!$I$2:$I$3451*'DGE links'!$J$2:$J$3451)/SUMPRODUCT(('DGE links'!$F$2:$F$3451=A24)*'DGE links'!$H$2:$H$3451*'DGE links'!$J$2:$J$3451),"") -> 0.50057619 | K24: =IFERROR(AVERAGEIFS('ILO links'!$H$2:$H$674,'ILO links'!$G$2:$G$674,A24,'ILO links'!$J$2:$J$674,1),"") -> 0.46727273 | L24: =IF(AND(ISNUMBER(J24),ISNUMBER(K24)),J24-K24,"") -> 0.033303463 | M24: =IF(ISNUMBER(L24),ABS(L24),"") -> 0.033303463 | N24: =IF(ISNUMBER(M24),IF(M24<=Summary!$B$4,"Agree","Check"),IF(ISNUMBER(J24),"DGE only",IF(ISNUMBER(K24),"ILO only","Not scored"))) -> Agree | O24: =IF(ISNUMBER(J24),J24,IF(ISNUMBER(K24),K24,"")) -> 0.50057619 | P24: =IF(ISNUMBER(J24),"DGE",IF(ISNUMBER(K24),"ILO table","")) -> DGE
A25: 242 | B25: 261 | C25: Legal professionals | D25: 261 | E25: 261 | F25: 261 | G25: 1 | H25: =SUMPRODUCT(('DGE links'!$F$2:$F$3451=A25)*1) -> 35 | I25: =SUMPRODUCT(('ILO links'!$G$2:$G$674=A25)*'ILO links'!$J$2:$J$674) -> 3 | J25: =IFERROR(SUMPRODUCT(('DGE links'!$F$2:$F$3451=A25)*'DGE links'!$H$2:$H$3451*'DGE links'!$I$2:$I$3451*'DGE links'!$J$2:$J$3451)/SUMPRODUCT(('DGE links'!$F$2:$F$3451=A25)*'DGE links'!$H$2:$H$3451*'DGE links'!$J$2:$J$3451),"") -> 0.3467 | K25: =IFERROR(AVERAGEIFS('ILO links'!$H$2:$H$674,'ILO links'!$G$2:$G$674,A25,'ILO links'!$J$2:$J$674,1),"") -> 0.34666667 | L25: =IF(AND(ISNUMBER(J25),ISNUMBER(K25)),J25-K25,"") -> 3.3333333e-05 | M25: =IF(ISNUMBER(L25),ABS(L25),"") -> 3.3333333e-05 | N25: =IF(ISNUMBER(M25),IF(M25<=Summary!$B$4,"Agree","Check"),IF(ISNUMBER(J25),"DGE only",IF(ISNUMBER(K25),"ILO only","Not scored"))) -> Agree | O25: =IF(ISNUMBER(J25),J25,IF(ISNUMBER(K25),K25,"")) -> 0.3467 | P25: =IF(ISNUMBER(J25),"DGE",IF(ISNUMBER(K25),"ILO table","")) -> DGE
A26: 243 | B26: 262 | C26: Librarians, archivists and curators | D26: 262 | E26: 262 | F26: 262 | G26: 1 | H26: =SUMPRODUCT(('DGE links'!$F$2:$F$3451=A26)*1) -> 13 | I26: =SUMPRODUCT(('ILO links'!$G$2:$G$674=A26)*'ILO links'!$J$2:$J$674) -> 2 | J26: =IFERROR(SUMPRODUCT(('DGE links'!$F$2:$F$3451=A26)*'DGE links'!$H$2:$H$3451*'DGE links'!$I$2:$I$3451*'DGE links'!$J$2:$J$3451)/SUMPRODUCT(('DGE links'!$F$2:$F$3451=A26)*'DGE links'!$H$2:$H$3451*'DGE links'!$J$2:$J$3451),"") -> 0.51 | K26: =IFERROR(AVERAGEIFS('ILO links'!$H$2:$H$674,'ILO links'!$G$2:$G$674,A26,'ILO links'!$J$2:$J$674,1),"") -> 0.51 | L26: =IF(AND(ISNUMBER(J26),ISNUMBER(K26)),J26-K26,"") -> 0 | M26: =IF(ISNUMBER(L26),ABS(L26),"") -> 0 | N26: =IF(ISNUMBER(M26),IF(M26<=Summary!$B$4,"Agree","Check"),IF(ISNUMBER(J26),"DGE only",IF(ISNUMBER(K26),"ILO only","Not scored"))) -> Agree | O26: =IF(ISNUMBER(J26),J26,IF(ISNUMBER(K26),K26,"")) -> 0.51 | P26: =IF(ISNUMBER(J26),"DGE",IF(ISNUMBER(K26),"ILO table","")) -> DGE
A27: 244 | B27: 263 | C27: Social and religious professionals | D27: 263 264 | E27: 263 264 | F27: 263 264 | G27: 1 | H27: =SUMPRODUCT(('DGE links'!$F$2:$F$3451=A27)*1) -> 49 | I27: =SUMPRODUCT(('ILO links'!$G$2:$G$674=A27)*'ILO links'!$J$2:$J$674) -> 6 | J27: =IFERROR(SUMPRODUCT(('DGE links'!$F$2:$F$3451=A27)*'DGE links'!$H$2:$H$3451*'DGE links'!$I$2:$I$3451*'DGE links'!$J$2:$J$3451)/SUMPRODUCT(('DGE links'!$F$2:$F$3451=A27)*'DGE links'!$H$2:$H$3451*'DGE links'!$J$2:$J$3451),"") -> 0.40387755 | K27: =IFERROR(AVERAGEIFS('ILO links'!$H$2:$H$674,'ILO links'!$G$2:$G$674,A27,'ILO links'!$J$2:$J$674,1),"") -> 0.46 | L27: =IF(AND(ISNUMBER(J27),ISNUMBER(K27)),J27-K27,"") -> -0.056122449 | M27: =IF(ISNUMBER(L27),ABS(L27),"") -> 0.056122449 | N27: =IF(ISNUMBER(M27),IF(M27<=Summary!$B$4,"Agree","Check"),IF(ISNUMBER(J27),"DGE only",IF(ISNUMBER(K27),"ILO only","Not scored"))) -> Check | O27: =IF(ISNUMBER(J27),J27,IF(ISNUMBER(K27),K27,"")) -> 0.40387755 | P27: =IF(ISNUMBER(J27),"DGE",IF(ISNUMBER(K27),"ILO table","")) -> DGE
A28: 245 | B28: 265 | C28: Creative and performing artists | D28: 216 243 264 265 | E28: 264 265 | F28: 264 265 | G28: 0.5 | H28: =SUMPRODUCT(('DGE links'!$F$2:$F$3451=A28)*1) -> 44 | I28: =SUMPRODUCT(('ILO links'!$G$2:$G$674=A28)*'ILO links'!$J$2:$J$674) -> 7 | J28: =IFERROR(SUMPRODUCT(('DGE links'!$F$2:$F$3451=A28)*'DGE links'!$H$2:$H$3451*'DGE links'!$I$2:$I$3451*'DGE links'!$J$2:$J$3451)/SUMPRODUCT(('DGE links'!$F$2:$F$3451=A28)*'DGE links'!$H$2:$H$3451*'DGE links'!$J$2:$J$3451),"") -> 0.38607955 | K28: =IFERROR(AVERAGEIFS('ILO links'!$H$2:$H$674,'ILO links'!$G$2:$G$674,A28,'ILO links'!$J$2:$J$674,1),"") -> 0.35 | L28: =IF(AND(ISNUMBER(J28),ISNUMBER(K28)),J28-K28,"") -> 0.036079545 | M28: =IF(ISNUMBER(L28),ABS(L28),"") -> 0.036079545 | N28: =IF(ISNUMBER(M28),IF(M28<=Summary!$B$4,"Agree","Check"),IF(ISNUMBER(J28),"DGE only",IF(ISNUMBER(K28),"ILO only","Not scored"))) -> Agree | O28: =IF(ISNUMBER(J28),J28,IF(ISNUMBER(K28),K28,"")) -> 0.38607955 | P28: =IF(ISNUMBER(J28),"DGE",IF(ISNUMBER(K28),"ILO table","")) -> DGE
A29: 246 | B29: 263 | C29: Social and religious professionals | D29: 263 | E29: 263 | F29: 263 | G29: 1 | H29: =SUMPRODUCT(('DGE links'!$F$2:$F$3451=A29)*1) -> 3 | I29: =SUMPRODUCT(('ILO links'!$G$2:$G$674=A29)*'ILO links'!$J$2:$J$674) -> 1 | J29: =IFERROR(SUMPRODUCT(('DGE links'!$F$2:$F$3451=A29)*'DGE links'!$H$2:$H$3451*'DGE links'!$I$2:$I$3451*'DGE links'!$J$2:$J$3451)/SUMPRODUCT(('DGE links'!$F$2:$F$3451=A29)*'DGE links'!$H$2:$H$3451*'DGE links'!$J$2:$J$3451),"") -> 0.39 | K29: =IFERROR(AVERAGEIFS('ILO links'!$H$2:$H$674,'ILO links'!$G$2:$G$674,A29,'ILO links'!$J$2:$J$674,1),"") -> 0.17 | L29: =IF(AND(ISNUMBER(J29),ISNUMBER(K29)),J29-K29,"") -> 0.22 | M29: =IF(ISNUMBER(L29),ABS(L29),"") -> 0.22 | N29: =IF(ISNUMBER(M29),IF(M29<=Summary!$B$4,"Agree","Check"),IF(ISNUMBER(J29),"DGE only",IF(ISNUMBER(K29),"ILO only","Not scored"))) -> Check | O29: =IF(ISNUMBER(J29),J29,IF(ISNUMBER(K29),K29,"")) -> 0.39 | P29: =IF(ISNUMBER(J29),"DGE",IF(ISNUMBER(K29),"ILO table","")) -> DGE
A30: 311 | B30: 311 | C30: Physical and engineering science technicians | D30: 311 352 | E30: 311 352 | F30: 311 352 | G30: 1 | H30: =SUMPRODUCT(('DGE links'!$F$2:$F$3451=A30)*1) -> 63 | I30: =SUMPRODUCT(('ILO links'!$G$2:$G$674=A30)*'ILO links'!$J$2:$J$674) -> 10 | J30: =IFERROR(SUMPRODUCT(('DGE links'!$F$2:$F$3451=A30)*'DGE links'!$H$2:$H$3451*'DGE links'!$I$2:$I$3451*'DGE links'!$J$2:$J$3451)/SUMPRODUCT(('DGE links'!$F$2:$F$3451=A30)*'DGE links'!$H$2:$H$3451*'DGE links'!$J$2:$J$3451),"") -> 0.30233548 | K30: =IFERROR(AVERAGEIFS('ILO links'!$H$2:$H$674,'ILO links'!$G$2:$G$674,A30,'ILO links'!$J$2:$J$674,1),"") -> 0.311 | L30: =IF(AND(ISNUMBER(J30),ISNUMBER(K30)),J30-K30,"") -> -0.0086645161 | M30: =IF(ISNUMBER(L30),ABS(L30),"") -> 0.0086645161 | N30: =IF(ISNUMBER(M30),IF(M30<=Summary!$B$4,"Agree","Check"),IF(ISNUMBER(J30),"DGE only",IF(ISNUMBER(K30),"ILO only","Not scored"))) -> Agree | O30: =IF(ISNUMBER(J30),J30,IF(ISNUMBER(K30),K30,"")) -> 0.30233548 | P30: =IF(ISNUMBER(J30),"DGE",IF(ISNUMBER(K30),"ILO table","")) -> DGE
A31: 312 | B31: 351 | C31: Information and communications technology operations and user support technicians | D31: 351 | E31: 313 351 | F31: 351 | G31: 0.5 | H31: =SUMPRODUCT(('DGE links'!$F$2:$F$3451=A31)*1) -> 7 | I31: =SUMPRODUCT(('ILO links'!$G$2:$G$674=A31)*'ILO links'!$J$2:$J$674) -> 5 | J31: =IFERROR(SUMPRODUCT(('DGE links'!$F$2:$F$3451=A31)*'DGE links'!$H$2:$H$3451*'DGE links'!$I$2:$I$3451*'DGE links'!$J$2:$J$3451)/SUMPRODUCT(('DGE links'!$F$2:$F$3451=A31)*'DGE links'!$H$2:$H$3451*'DGE links'!$J$2:$J$3451),"") -> 0.465 | K31: =IFERROR(AVERAGEIFS('ILO links'!$H$2:$H$674,'ILO links'!$G$2:$G$674,A31,'ILO links'!$J$2:$J$674,1),"") -> 0.465 | L31: =IF(AND(ISNUMBER(J31),ISNUMBER(K31)),J31-K31,"") -> 0 | M31: =IF(ISNUMBER(L31),ABS(L31),"") -> 0 | N31: =IF(ISNUMBER(M31),IF(M31<=Summary!$B$4,"Agree","Check"),IF(ISNUMBER(J31),"DGE only",IF(ISNUMBER(K31),"ILO only","Not scored"))) -> Agree | O31: =IF(ISNUMBER(J31),J31,IF(ISNUMBER(K31),K31,"")) -> 0.465 | P31: =IF(ISNUMBER(J31),"DGE",IF(ISNUMBER(K31),"ILO table","")) -> DGE
A32: 313 | B32: 352 | C32: Telecommunications and broadcasting technicians | D32: 311 321 343 352 | E32: 321 343 352 | F32: 321 343 352 | G32: 0.75 | H32: =SUMPRODUCT(('DGE links'!$F$2:$F$3451=A32)*1) -> 29 | I32: =SUMPRODUCT(('ILO links'!$G$2:$G$674=A32)*'ILO links'!$J$2:$J$674) -> 4 | J32: =IFERROR(SUMPRODUCT(('DGE links'!$F$2:$F$3451=A32)*'DGE links'!$H$2:$H$3451*'DGE links'!$I$2:$I$3451*'DGE links'!$J$2:$J$3451)/SUMPRODUCT(('DGE links'!$F$2:$F$3451=A32)*'DGE links'!$H$2:$H$3451*'DGE links'!$J$2:$J$3451),"") -> 0.36995517 | K32: =IFERROR(AVERAGEIFS('ILO links'!$H$2:$H$674,'ILO links'!$G$2:$G$674,A32,'ILO links'!$J$2:$J$674,1),"") -> 0.3525 | L32: =IF(AND(ISNUMBER(J32),ISNUMBER(K32)),J32-K32,"") -> 0.017455172 | M32: =IF(ISNUMBER(L32),ABS(L32),"") -> 0.017455172 | N32: =IF(ISNUMBER(M32),IF(M32<=Summary!$B$4,"Agree","Check"),IF(ISNUMBER(J32),"DGE only",IF(ISNUMBER(K32),"ILO only","Not scored"))) -> Agree | O32: =IF(ISNUMBER(J32),J32,IF(ISNUMBER(K32),K32,"")) -> 0.36995517 | P32: =IF(ISNUMBER(J32),"DGE",IF(ISNUMBER(K32),"ILO table","")) -> DGE
A33: 314 | B33: 315 | C33: Ship and aircraft controllers and technicians | D33: 315 | E33: 315 | F33: 315 | G33: 1 | H33: =SUMPRODUCT(('DGE links'!$F$2:$F$3451=A33)*1) -> 29 | I33: =SUMPRODUCT(('ILO links'!$G$2:$G$674=A33)*'ILO links'!$J$2:$J$674) -> 5 | J33: =IFERROR(SUMPRODUCT(('DGE links'!$F$2:$F$3451=A33)*'DGE links'!$H$2:$H$3451*'DGE links'!$I$2:$I$3451*'DGE links'!$J$2:$J$3451)/SUMPRODUCT(('DGE links'!$F$2:$F$3451=A33)*'DGE links'!$H$2:$H$3451*'DGE links'!$J$2:$J$3451),"") -> 0.288 | K33: =IFERROR(AVERAGEIFS('ILO links'!$H$2:$H$674,'ILO links'!$G$2:$G$674,A33,'ILO links'!$J$2:$J$674,1),"") -> 0.288 | L33: =IF(AND(ISNUMBER(J33),ISNUMBER(K33)),J33-K33,"") -> 0 | M33: =IF(ISNUMBER(L33),ABS(L33),"") -> 0 | N33: =IF(ISNUMBER(M33),IF(M33<=Summary!$B$4,"Agree","Check"),IF(ISNUMBER(J33),"DGE only",IF(ISNUMBER(K33),"ILO only","Not scored"))) -> Agree | O33: =IF(ISNUMBER(J33),J33,IF(ISNUMBER(K33),K33,"")) -> 0.288 | P33: =IF(ISNUMBER(J33),"DGE",IF(ISNUMBER(K33),"ILO table","")) -> DGE
A34: 315 | B34: 311 | C34: Physical and engineering science technicians | D34: 226 311 754 | E34: 226 311 325 335 754 | F34: 226 311 754 | G34: 0.6 | H34: =SUMPRODUCT(('DGE links'!$F$2:$F$3451=A34)*1) -> 9 | I34: =SUMPRODUCT(('ILO links'!$G$2:$G$674=A34)*'ILO links'!$J$2:$J$674) -> 9 | J34: =IFERROR(SUMPRODUCT(('DGE links'!$F$2:$F$3451=A34)*'DGE links'!$H$2:$H$3451*'DGE links'!$I$2:$I$3451*'DGE links'!$J$2:$J$3451)/SUMPRODUCT(('DGE links'!$F$2:$F$3451=A34)*'DGE links'!$H$2:$H$3451*'DGE links'!$J$2:$J$3451),"") -> 0.2374 | K34: =IFERROR(AVERAGEIFS('ILO links'!$H$2:$H$674,'ILO links'!$G$2:$G$674,A34,'ILO links'!$J$2:$J$674,1),"") -> 0.29555556 | L34: =IF(AND(ISNUMBER(J34),ISNUMBER(K34)),J34-K34,"") -> -0.058155556 | M34: =IF(ISNUMBER(L34),ABS(L34),"") -> 0.058155556 | N34: =IF(ISNUMBER(M34),IF(M34<=Summary!$B$4,"Agree","Check"),IF(ISNUMBER(J34),"DGE only",IF(ISNUMBER(K34),"ILO only","Not scored"))) -> Check | O34: =IF(ISNUMBER(J34),J34,IF(ISNUMBER(K34),K34,"")) -> 0.2374 | P34: =IF(ISNUMBER(J34),"DGE",IF(ISNUMBER(K34),"ILO table","")) -> DGE
A35: 321 | B35: 325 | C35: Other health associate professionals | D35: 213 314 321 325 | E35: 213 314 321 | F35: 213 314 321 | G35: 0.75 | H35: =SUMPRODUCT(('DGE links'!$F$2:$F$3451=A35)*1) -> 11 | I35: =SUMPRODUCT(('ILO links'!$G$2:$G$674=A35)*'ILO links'!$J$2:$J$674) -> 5 | J35: =IFERROR(SUMPRODUCT(('DGE links'!$F$2:$F$3451=A35)*'DGE links'!$H$2:$H$3451*'DGE links'!$I$2:$I$3451*'DGE links'!$J$2:$J$3451)/SUMPRODUCT(('DGE links'!$F$2:$F$3451=A35)*'DGE links'!$H$2:$H$3451*'DGE links'!$J$2:$J$3451),"") -> 0.27633636 | K35: =IFERROR(AVERAGEIFS('ILO links'!$H$2:$H$674,'ILO links'!$G$2:$G$674,A35,'ILO links'!$J$2:$J$674,1),"") -> 0.29 | L35: =IF(AND(ISNUMBER(J35),ISNUMBER(K35)),J35-K35,"") -> -0.013663636 | M35: =IF(ISNUMBER(L35),ABS(L35),"") -> 0.013663636 | N35: =IF(ISNUMBER(M35),IF(M35<=Summary!$B$4,"Agree","Check"),IF(ISNUMBER(J35),"DGE only",IF(ISNUMBER(K35),"ILO only","Not scored"))) -> Agree | O35: =IF(ISNUMBER(J35),J35,IF(ISNUMBER(K35),K35,"")) -> 0.27633636 | P35: =IF(ISNUMBER(J35),"DGE",IF(ISNUMBER(K35),"ILO table","")) -> DGE
... A49: 347 | B49: 265 | C49: Creative and performing artists | D49: 216 265 342 343 | E49: 216 264 265 342 343 731 | F49: 216 265 342 343 | G49: 0.66666667 | H49: =SUMPRODUCT(('DGE links'!$F$2:$F$3451=A49)*1) -> 40 | I49: =SUMPRODUCT(('ILO links'!$G$2:$G$674=A49)*'ILO links'!$J$2:$J$674) -> 13 | J49: =IFERROR(SUMPRODUCT(('DGE links'!$F$2:$F$3451=A49)*'DGE links'!$H$2:$H$3451*'DGE links'!$I$2:$I$3451*'DGE links'!$J$2:$J$3451)/SUMPRODUCT(('DGE links'!$F$2:$F$3451=A49)*'DGE links'!$H$2:$H$3451*'DGE links'!$J$2:$J$3451),"") -> 0.3109925 | K49: =IFERROR(AVERAGEIFS('ILO links'!$H$2:$H$674,'ILO links'!$G$2:$G$674,A49,'ILO links'!$J$2:$J$674,1),"") -> 0.32461538 | L49: =IF(AND(ISNUMBER(J49),ISNUMBER(K49)),J49-K49,"") -> -0.013622885 | M49: =IF(ISNUMBER(L49),ABS(L49),"") -> 0.013622885 | N49: =IF(ISNUMBER(M49),IF(M49<=Summary!$B$4,"Agree","Check"),IF(ISNUMBER(J49),"DGE only",IF(ISNUMBER(K49),"ILO only","Not scored"))) -> Agree | O49: =IF(ISNUMBER(J49),J49,IF(ISNUMBER(K49),K49,"")) -> 0.3109925 | P49: =IF(ISNUMBER(J49),"DGE",IF(ISNUMBER(K49),"ILO table","")) -> DGE
A50: 348 | E50: 341 | H50: =SUMPRODUCT(('DGE links'!$F$2:$F$3451=A50)*1) -> 0 | I50: =SUMPRODUCT(('ILO links'!$G$2:$G$674=A50)*'ILO links'!$J$2:$J$674) -> 1 | J50: =IFERROR(SUMPRODUCT(('DGE links'!$F$2:$F$3451=A50)*'DGE links'!$H$2:$H$3451*'DGE links'!$I$2:$I$3451*'DGE links'!$J$2:$J$3451)/SUMPRODUCT(('DGE links'!$F$2:$F$3451=A50)*'DGE links'!$H$2:$H$3451*'DGE links'!$J$2:$J$3451),"") | K50: =IFERROR(AVERAGEIFS('ILO links'!$H$2:$H$674,'ILO links'!$G$2:$G$674,A50,'ILO links'!$J$2:$J$674,1),"") -> 0.12 | L50: =IF(AND(ISNUMBER(J50),ISNUMBER(K50)),J50-K50,"") | M50: =IF(ISNUMBER(L50),ABS(L50),"") | N50: =IF(ISNUMBER(M50),IF(M50<=Summary!$B$4,"Agree","Check"),IF(ISNUMBER(J50),"DGE only",IF(ISNUMBER(K50),"ILO only","Not scored"))) -> ILO only | O50: =IF(ISNUMBER(J50),J50,IF(ISNUMBER(K50),K50,"")) -> 0.12 | P50: =IF(ISNUMBER(J50),"DGE",IF(ISNUMBER(K50),"ILO table","")) -> ILO table
A51: 411 | B51: 413 | C51: Keyboard operators | D51: 412 413 | E51: 334 412 413 | F51: 412 413 | G51: 0.66666667 | H51: =SUMPRODUCT(('DGE links'!$F$2:$F$3451=A51)*1) -> 18 | I51: =SUMPRODUCT(('ILO links'!$G$2:$G$674=A51)*'ILO links'!$J$2:$J$674) -> 6 | J51: =IFERROR(SUMPRODUCT(('DGE links'!$F$2:$F$3451=A51)*'DGE links'!$H$2:$H$3451*'DGE links'!$I$2:$I$3451*'DGE links'!$J$2:$J$3451)/SUMPRODUCT(('DGE links'!$F$2:$F$3451=A51)*'DGE links'!$H$2:$H$3451*'DGE links'!$J$2:$J$3451),"") -> 0.65388889 | K51: =IFERROR(AVERAGEIFS('ILO links'!$H$2:$H$674,'ILO links'!$G$2:$G$674,A51,'ILO links'!$J$2:$J$674,1),"") -> 0.57333333 | L51: =IF(AND(ISNUMBER(J51),ISNUMBER(K51)),J51-K51,"") -> 0.080555556 | M51: =IF(ISNUMBER(L51),ABS(L51),"") -> 0.080555556 | N51: =IF(ISNUMBER(M51),IF(M51<=Summary!$B$4,"Agree","Check"),IF(ISNUMBER(J51),"DGE only",IF(ISNUMBER(K51),"ILO only","Not scored"))) -> Check | O51: =IF(ISNUMBER(J51),J51,IF(ISNUMBER(K51),K51,"")) -> 0.65388889 | P51: =IF(ISNUMBER(J51),"DGE",IF(ISNUMBER(K51),"ILO table","")) -> DGE
A52: 412 | B52: 431 | C52: Numerical clerks | D52: 431 | E52: 334 431 | F52: 431 | G52: 0.5 | H52: =SUMPRODUCT(('DGE links'!$F$2:$F$3451=A52)*1) -> 10 | I52: =SUMPRODUCT(('ILO links'!$G$2:$G$674=A52)*'ILO links'!$J$2:$J$674) -> 4 | J52: =IFERROR(SUMPRODUCT(('DGE links'!$F$2:$F$3451=A52)*'DGE links'!$H$2:$H$3451*'DGE links'!$I$2:$I$3451*'DGE links'!$J$2:$J$3451)/SUMPRODUCT(('DGE links'!$F$2:$F$3451=A52)*'DGE links'!$H$2:$H$3451*'DGE links'!$J$2:$J$3451),"") -> 0.63 | K52: =IFERROR(AVERAGEIFS('ILO links'!$H$2:$H$674,'ILO links'!$G$2:$G$674,A52,'ILO links'!$J$2:$J$674,1),"") -> 0.58 | L52: =IF(AND(ISNUMBER(J52),ISNUMBER(K52)),J52-K52,"") -> 0.05 | M52: =IF(ISNUMBER(L52),ABS(L52),"") -> 0.05 | N52: =IF(ISNUMBER(M52),IF(M52<=Summary!$B$4,"Agree","Check"),IF(ISNUMBER(J52),"DGE only",IF(ISNUMBER(K52),"ILO only","Not scored"))) -> Agree | O52: =IF(ISNUMBER(J52),J52,IF(ISNUMBER(K52),K52,"")) -> 0.63 | P52: =IF(ISNUMBER(J52),"DGE",IF(ISNUMBER(K52),"ILO table","")) -> DGE
A53: 413 | B53: 432 | C53: Material-recording and transport clerks | D53: 432 | E53: 334 432 | F53: 432 | G53: 0.5 | H53: =SUMPRODUCT(('DGE links'!$F$2:$F$3451=A53)*1) -> 10 | I53: =SUMPRODUCT(('ILO links'!$G$2:$G$674=A53)*'ILO links'!$J$2:$J$674) -> 4 | J53: =IFERROR(SUMPRODUCT(('DGE links'!$F$2:$F$3451=A53)*'DGE links'!$H$2:$H$3451*'DGE links'!$I$2:$I$3451*'DGE links'!$J$2:$J$3451)/SUMPRODUCT(('DGE links'!$F$2:$F$3451=A53)*'DGE links'!$H$2:$H$3451*'DGE links'!$J$2:$J$3451),"") -> 0.4367 | K53: =IFERROR(AVERAGEIFS('ILO links'!$H$2:$H$674,'ILO links'!$G$2:$G$674,A53,'ILO links'!$J$2:$J$674,1),"") -> 0.435 | L53: =IF(AND(ISNUMBER(J53),ISNUMBER(K53)),J53-K53,"") -> 0.0017 | M53: =IF(ISNUMBER(L53),ABS(L53),"") -> 0.0017 | N53: =IF(ISNUMBER(M53),IF(M53<=Summary!$B$4,"Agree","Check"),IF(ISNUMBER(J53),"DGE only",IF(ISNUMBER(K53),"ILO only","Not scored"))) -> Agree | O53: =IF(ISNUMBER(J53),J53,IF(ISNUMBER(K53),K53,"")) -> 0.4367 | P53: =IF(ISNUMBER(J53),"DGE",IF(ISNUMBER(K53),"ILO table","")) -> DGE
...

Sheet NCO-2015 scores
A1: NCO-2015 group | B1: Group title (ISCO-08) | C1: ILO exposure score (0-1) | D1: Share of jobs in ILO gradients 3-4
A2: 011 | B2: Commissioned armed forces officers
A3: 021 | B3: Non-commissioned armed forces officers
A4: 031 | B4: Armed forces occupations, other ranks
A5: 111 | B5: Legislators and senior officials | C5: 0.3225 | D5: 0
A6: 112 | B6: Managing directors and chief executives | C6: 0.38 | D6: 0
A7: 121 | B7: Business services and administration managers | C7: 0.3775 | D7: 0
A8: 122 | B8: Sales, marketing and development managers | C8: 0.4 | D8: 0
A9: 131 | B9: Production managers in agriculture, forestry and fisheries | C9: 0.245 | D9: 0
A10: 132 | B10: Manufacturing, mining, construction, and distribution managers | C10: 0.3625 | D10: 0
A11: 133 | B11: Information and communications technology service managers | C11: 0.44 | D11: 0
A12: 134 | B12: Professional services managers | C12: 0.3686 | D12: 0
A13: 141 | B13: Hotel and restaurant managers | C13: 0.365 | D13: 0
A14: 142 | B14: Retail and wholesale trade managers | C14: 0.44 | D14: 0
A15: 143 | B15: Other services managers | C15: 0.32 | D15: 0
A16: 211 | B16: Physical and earth science professionals | C16: 0.4175 | D16: 0.25
... A131: 962 | B131: Other elementary workers | C131: 0.248 | D131: 0
A133: Source: Mishra, nco2015-ai-exposure (github.com/Kpmishra1998/nco2015-ai-exposure), built from ILO WP140 (Gmyrek et al. 2025) Table A1. Blue = input values.

Sheet DGE links
A1: S.No. | B1: Occupational title | C1: NCO-2015 code | D1: NCO-2004 code | E1: NCO-2015 group | F1: NCO-2004 group | G1: Same 3-digit number? | H1: Weight (1 / links of this 2004 code) | I1: Exposure of NCO-2015 group | J1: Has score (1/0)
A2: 1 | B2: Accountant | C2: 2411.0100 | D2: 2411.10 | E2: =LEFT(C2,3) -> 241 | F2: =IF(D2="","",LEFT(D2,3)) -> 241 | G2: =IF(F2="","",IF(E2=F2,"Yes","No")) -> Yes | H2: =IF(D2="",0,1/COUNTIF($D$2:$D$3451,D2)) -> 1 | I2: =IFERROR(INDEX('NCO-2015 scores'!$C$2:$C$131,MATCH(E2,'NCO-2015 scores'!$A$2:$A$131,0)),0) -> 0.5667 | J2: =IF(ISNUMBER(MATCH(E2,'NCO-2015 scores'!$A$2:$A$131,0)),IF(ISNUMBER(INDEX('NCO-2015 scores'!$C$2:$C$131,MATCH(E2,'NCO-2015 scores'!$A$2:$A$131,0))),1,0),0) -> 1
A3: 2 | B3: Auditor | C3: 2411.0200 | D3: 2411.20 | E3: =LEFT(C3,3) -> 241 | F3: =IF(D3="","",LEFT(D3,3)) -> 241 | G3: =IF(F3="","",IF(E3=F3,"Yes","No")) -> Yes | H3: =IF(D3="",0,1/COUNTIF($D$2:$D$3451,D3)) -> 1 | I3: =IFERROR(INDEX('NCO-2015 scores'!$C$2:$C$131,MATCH(E3,'NCO-2015 scores'!$A$2:$A$131,0)),0) -> 0.5667 | J3: =IF(ISNUMBER(MATCH(E3,'NCO-2015 scores'!$A$2:$A$131,0)),IF(ISNUMBER(INDEX('NCO-2015 scores'!$C$2:$C$131,MATCH(E3,'NCO-2015 scores'!$A$2:$A$131,0))),1,0),0) -> 1
A4: 3 | B4: Cost Accountant | C4: 2411.0300 | D4: 2411.30 | E4: =LEFT(C4,3) -> 241 | F4: =IF(D4="","",LEFT(D4,3)) -> 241 | G4: =IF(F4="","",IF(E4=F4,"Yes","No")) -> Yes | H4: =IF(D4="",0,1/COUNTIF($D$2:$D$3451,D4)) -> 1 | I4: =IFERROR(INDEX('NCO-2015 scores'!$C$2:$C$131,MATCH(E4,'NCO-2015 scores'!$A$2:$A$131,0)),0) -> 0.5667 | J4: =IF(ISNUMBER(MATCH(E4,'NCO-2015 scores'!$A$2:$A$131,0)),IF(ISNUMBER(INDEX('NCO-2015 scores'!$C$2:$C$131,MATCH(E4,'NCO-2015 scores'!$A$2:$A$131,0))),1,0),0) -> 1
A5: 4 | B5: Associate – Transactional Finance & Accounting | C5: 2411.0101 | E5: =LEFT(C5,3) -> 241 | F5: =IF(D5="","",LEFT(D5,3)) | G5: =IF(F5="","",IF(E5=F5,"Yes","No")) | H5: =IF(D5="",0,1/COUNTIF($D$2:$D$3451,D5)) -> 0 | I5: =IFERROR(INDEX('NCO-2015 scores'!$C$2:$C$131,MATCH(E5,'NCO-2015 scores'!$A$2:$A$131,0)),0) -> 0.5667 | J5: =IF(ISNUMBER(MATCH(E5,'NCO-2015 scores'!$A$2:$A$131,0)),IF(ISNUMBER(INDEX('NCO-2015 scores'!$C$2:$C$131,MATCH(E5,'NCO-2015 scores'!$A$2:$A$131,0))),1,0),0) -> 1
A6: 5 | B6: Associate – Finance & Accounting Complex | C6: 2411.0201 | E6: =LEFT(C6,3) -> 241 | F6: =IF(D6="","",LEFT(D6,3)) | G6: =IF(F6="","",IF(E6=F6,"Yes","No")) | H6: =IF(D6="",0,1/COUNTIF($D$2:$D$3451,D6)) -> 0 | I6: =IFERROR(INDEX('NCO-2015 scores'!$C$2:$C$131,MATCH(E6,'NCO-2015 scores'!$A$2:$A$131,0)),0) -> 0.5667 | J6: =IF(ISNUMBER(MATCH(E6,'NCO-2015 scores'!$A$2:$A$131,0)),IF(ISNUMBER(INDEX('NCO-2015 scores'!$C$2:$C$131,MATCH(E6,'NCO-2015 scores'!$A$2:$A$131,0))),1,0),0) -> 1
A7: 6 | B7: Bookkeeper General/Accounts Executive (Recording and Reporting) | C7: 4311.0101 | D7: 4121.10 | E7: =LEFT(C7,3) -> 431 | F7: =IF(D7="","",LEFT(D7,3)) -> 412 | G7: =IF(F7="","",IF(E7=F7,"Yes","No")) -> No | H7: =IF(D7="",0,1/COUNTIF($D$2:$D$3451,D7)) -> 1 | I7: =IFERROR(INDEX('NCO-2015 scores'!$C$2:$C$131,MATCH(E7,'NCO-2015 scores'!$A$2:$A$131,0)),0) -> 0.63 | J7: =IF(ISNUMBER(MATCH(E7,'NCO-2015 scores'!$A$2:$A$131,0)),IF(ISNUMBER(INDEX('NCO-2015 scores'!$C$2:$C$131,MATCH(E7,'NCO-2015 scores'!$A$2:$A$131,0))),1,0),0) -> 1
A8: 7 | B8: Bank Clerk | C8: 4311.0200 | D8: 4121.30 | E8: =LEFT(C8,3) -> 431 | F8: =IF(D8="","",LEFT(D8,3)) -> 412 | G8: =IF(F8="","",IF(E8=F8,"Yes","No")) -> No | H8: =IF(D8="",0,1/COUNTIF($D$2:$D$3451,D8)) -> 1 | I8: =IFERROR(INDEX('NCO-2015 scores'!$C$2:$C$131,MATCH(E8,'NCO-2015 scores'!$A$2:$A$131,0)),0) -> 0.63 | J8: =IF(ISNUMBER(MATCH(E8,'NCO-2015 scores'!$A$2:$A$131,0)),IF(ISNUMBER(INDEX('NCO-2015 scores'!$C$2:$C$131,MATCH(E8,'NCO-2015 scores'!$A$2:$A$131,0))),1,0),0) -> 1
A9: 8 | B9: Ledger Clerk | C9: 4311.0300 | D9: 4121.40 | E9: =LEFT(C9,3) -> 431 | F9: =IF(D9="","",LEFT(D9,3)) -> 412 | G9: =IF(F9="","",IF(E9=F9,"Yes","No")) -> No | H9: =IF(D9="",0,1/COUNTIF($D$2:$D$3451,D9)) -> 1 | I9: =IFERROR(INDEX('NCO-2015 scores'!$C$2:$C$131,MATCH(E9,'NCO-2015 scores'!$A$2:$A$131,0)),0) -> 0.63 | J9: =IF(ISNUMBER(MATCH(E9,'NCO-2015 scores'!$A$2:$A$131,0)),IF(ISNUMBER(INDEX('NCO-2015 scores'!$C$2:$C$131,MATCH(E9,'NCO-2015 scores'!$A$2:$A$131,0))),1,0),0) -> 1
A10: 9 | B10: Accounts Executive (Accounts Payable & Receivable) | C10: 4311.0401 | E10: =LEFT(C10,3) -> 431 | F10: =IF(D10="","",LEFT(D10,3)) | G10: =IF(F10="","",IF(E10=F10,"Yes","No")) | H10: =IF(D10="",0,1/COUNTIF($D$2:$D$3451,D10)) -> 0 | I10: =IFERROR(INDEX('NCO-2015 scores'!$C$2:$C$131,MATCH(E10,'NCO-2015 scores'!$A$2:$A$131,0)),0) -> 0.63 | J10: =IF(ISNUMBER(MATCH(E10,'NCO-2015 scores'!$A$2:$A$131,0)),IF(ISNUMBER(INDEX('NCO-2015 scores'!$C$2:$C$131,MATCH(E10,'NCO-2015 scores'!$A$2:$A$131,0))),1,0),0) -> 1
A11: 10 | B11: Audit, Clerk | C11: 4311.0500 | D11: 4121.50 | E11: =LEFT(C11,3) -> 431 | F11: =IF(D11="","",LEFT(D11,3)) -> 412 | G11: =IF(F11="","",IF(E11=F11,"Yes","No")) -> No | H11: =IF(D11="",0,1/COUNTIF($D$2:$D$3451,D11)) -> 1 | I11: =IFERROR(INDEX('NCO-2015 scores'!$C$2:$C$131,MATCH(E11,'NCO-2015 scores'!$A$2:$A$131,0)),0) -> 0.63 | J11: =IF(ISNUMBER(MATCH(E11,'NCO-2015 scores'!$A$2:$A$131,0)),IF(ISNUMBER(INDEX('NCO-2015 scores'!$C$2:$C$131,MATCH(E11,'NCO-2015 scores'!$A$2:$A$131,0))),1,0),0) -> 1
A12: 11 | B12: Clerk, Cost Accounting | C12: 4311.0600 | D12: 4121.60 | E12: =LEFT(C12,3) -> 431 | F12: =IF(D12="","",LEFT(D12,3)) -> 412 | G12: =IF(F12="","",IF(E12=F12,"Yes","No")) -> No | H12: =IF(D12="",0,1/COUNTIF($D$2:$D$3451,D12)) -> 1 | I12: =IFERROR(INDEX('NCO-2015 scores'!$C$2:$C$131,MATCH(E12,'NCO-2015 scores'!$A$2:$A$131,0)),0) -> 0.63 | J12: =IF(ISNUMBER(MATCH(E12,'NCO-2015 scores'!$A$2:$A$131,0)),IF(ISNUMBER(INDEX('NCO-2015 scores'!$C$2:$C$131,MATCH(E12,'NCO-2015 scores'!$A$2:$A$131,0))),1,0),0) -> 1
A13: 12 | B13: Bill and Accounts Collector | C13: 4311.0700 | D13: 4121.70 | E13: =LEFT(C13,3) -> 431 | F13: =IF(D13="","",LEFT(D13,3)) -> 412 | G13: =IF(F13="","",IF(E13=F13,"Yes","No")) -> No | H13: =IF(D13="",0,1/COUNTIF($D$2:$D$3451,D13)) -> 1 | I13: =IFERROR(INDEX('NCO-2015 scores'!$C$2:$C$131,MATCH(E13,'NCO-2015 scores'!$A$2:$A$131,0)),0) -> 0.63 | J13: =IF(ISNUMBER(MATCH(E13,'NCO-2015 scores'!$A$2:$A$131,0)),IF(ISNUMBER(INDEX('NCO-2015 scores'!$C$2:$C$131,MATCH(E13,'NCO-2015 scores'!$A$2:$A$131,0))),1,0),0) -> 1
A14: 13 | B14: Rubber Nursery Office Assistant | C14: 4311.0801 | E14: =LEFT(C14,3) -> 431 | F14: =IF(D14="","",LEFT(D14,3)) | G14: =IF(F14="","",IF(E14=F14,"Yes","No")) | H14: =IF(D14="",0,1/COUNTIF($D$2:$D$3451,D14)) -> 0 | I14: =IFERROR(INDEX('NCO-2015 scores'!$C$2:$C$131,MATCH(E14,'NCO-2015 scores'!$A$2:$A$131,0)),0) -> 0.63 | J14: =IF(ISNUMBER(MATCH(E14,'NCO-2015 scores'!$A$2:$A$131,0)),IF(ISNUMBER(INDEX('NCO-2015 scores'!$C$2:$C$131,MATCH(E14,'NCO-2015 scores'!$A$2:$A$131,0))),1,0),0) -> 1
A15: 14 | B15: Accounting and Bookkeeping Clerks, Others | C15: 4311.9900 | D15: 4121.90 | E15: =LEFT(C15,3) -> 431 | F15: =IF(D15="","",LEFT(D15,3)) -> 412 | G15: =IF(F15="","",IF(E15=F15,"Yes","No")) -> No | H15: =IF(D15="",0,1/COUNTIF($D$2:$D$3451,D15)) -> 1 | I15: =IFERROR(INDEX('NCO-2015 scores'!$C$2:$C$131,MATCH(E15,'NCO-2015 scores'!$A$2:$A$131,0)),0) -> 0.63 | J15: =IF(ISNUMBER(MATCH(E15,'NCO-2015 scores'!$A$2:$A$131,0)),IF(ISNUMBER(INDEX('NCO-2015 scores'!$C$2:$C$131,MATCH(E15,'NCO-2015 scores'!$A$2:$A$131,0))),1,0),0) -> 1
A16: 15 | B16: Actor and Actress | C16: 2655.0100 | D16: 2455.50 | E16: =LEFT(C16,3) -> 265 | F16: =IF(D16="","",LEFT(D16,3)) -> 245 | G16: =IF(F16="","",IF(E16=F16,"Yes","No")) -> No | H16: =IF(D16="",0,1/COUNTIF($D$2:$D$3451,D16)) -> 1 | I16: =IFERROR(INDEX('NCO-2015 scores'!$C$2:$C$131,MATCH(E16,'NCO-2015 scores'!$A$2:$A$131,0)),0) -> 0.28 | J16: =IF(ISNUMBER(MATCH(E16,'NCO-2015 scores'!$A$2:$A$131,0)),IF(ISNUMBER(INDEX('NCO-2015 scores'!$C$2:$C$131,MATCH(E16,'NCO-2015 scores'!$A$2:$A$131,0))),1,0),0) -> 1
A17: 16 | B17: Extra | C17: 2655.0200 | D17: 2455.60 | E17: =LEFT(C17,3) -> 265 | F17: =IF(D17="","",LEFT(D17,3)) -> 245 | G17: =IF(F17="","",IF(E17=F17,"Yes","No")) -> No | H17: =IF(D17="",0,1/COUNTIF($D$2:$D$3451,D17)) -> 1 | I17: =IFERROR(INDEX('NCO-2015 scores'!$C$2:$C$131,MATCH(E17,'NCO-2015 scores'!$A$2:$A$131,0)),0) -> 0.28 | J17: =IF(ISNUMBER(MATCH(E17,'NCO-2015 scores'!$A$2:$A$131,0)),IF(ISNUMBER(INDEX('NCO-2015 scores'!$C$2:$C$131,MATCH(E17,'NCO-2015 scores'!$A$2:$A$131,0))),1,0),0) -> 1
A18: 17 | B18: Voice Over Artist | C18: 2655.0301 | E18: =LEFT(C18,3) -> 265 | F18: =IF(D18="","",LEFT(D18,3)) | G18: =IF(F18="","",IF(E18=F18,"Yes","No")) | H18: =IF(D18="",0,1/COUNTIF($D$2:$D$3451,D18)) -> 0 | I18: =IFERROR(INDEX('NCO-2015 scores'!$C$2:$C$131,MATCH(E18,'NCO-2015 scores'!$A$2:$A$131,0)),0) -> 0.28 | J18: =IF(ISNUMBER(MATCH(E18,'NCO-2015 scores'!$A$2:$A$131,0)),IF(ISNUMBER(INDEX('NCO-2015 scores'!$C$2:$C$131,MATCH(E18,'NCO-2015 scores'!$A$2:$A$131,0))),1,0),0) -> 1
A19: 18 | B19: Caption Writer | C19: 2431.0300 | D19: 2451.47 | E19: =LEFT(C19,3) -> 243 | F19: =IF(D19="","",LEFT(D19,3)) -> 245 | G19: =IF(F19="","",IF(E19=F19,"Yes","No")) -> No | H19: =IF(D19="",0,1/COUNTIF($D$2:$D$3451,D19)) -> 1 | I19: =IFERROR(INDEX('NCO-2015 scores'!$C$2:$C$131,MATCH(E19,'NCO-2015 scores'!$A$2:$A$131,0)),0) -> 0.4975 | J19: =IF(ISNUMBER(MATCH(E19,'NCO-2015 scores'!$A$2:$A$131,0)),IF(ISNUMBER(INDEX('NCO-2015 scores'!$C$2:$C$131,MATCH(E19,'NCO-2015 scores'!$A$2:$A$131,0))),1,0),0) -> 1
A20: 19 | B20: Advertisement Writer | C20: 2431.0400 | D20: 2451.50 | E20: =LEFT(C20,3) -> 243 | F20: =IF(D20="","",LEFT(D20,3)) -> 245 | G20: =IF(F20="","",IF(E20=F20,"Yes","No")) -> No | H20: =IF(D20="",0,1/COUNTIF($D$2:$D$3451,D20)) -> 1 | I20: =IFERROR(INDEX('NCO-2015 scores'!$C$2:$C$131,MATCH(E20,'NCO-2015 scores'!$A$2:$A$131,0)),0) -> 0.4975 | J20: =IF(ISNUMBER(MATCH(E20,'NCO-2015 scores'!$A$2:$A$131,0)),IF(ISNUMBER(INDEX('NCO-2015 scores'!$C$2:$C$131,MATCH(E20,'NCO-2015 scores'!$A$2:$A$131,0))),1,0),0) -> 1
A21: 20 | B21: Market Research Analyst | C21: 2431.0100 | D21: 2419.40 | E21: =LEFT(C21,3) -> 243 | F21: =IF(D21="","",LEFT(D21,3)) -> 241 | G21: =IF(F21="","",IF(E21=F21,"Yes","No")) -> No | H21: =IF(D21="",0,1/COUNTIF($D$2:$D$3451,D21)) -> 1 | I21: =IFERROR(INDEX('NCO-2015 scores'!$C$2:$C$131,MATCH(E21,'NCO-2015 scores'!$A$2:$A$131,0)),0) -> 0.4975 | J21: =IF(ISNUMBER(MATCH(E21,'NCO-2015 scores'!$A$2:$A$131,0)),IF(ISNUMBER(INDEX('NCO-2015 scores'!$C$2:$C$131,MATCH(E21,'NCO-2015 scores'!$A$2:$A$131,0))),1,0),0) -> 1
A22: 21 | B22: Regional Service Marketing Manager | C22: 2431.0101 | E22: =LEFT(C22,3) -> 243 | F22: =IF(D22="","",LEFT(D22,3)) | G22: =IF(F22="","",IF(E22=F22,"Yes","No")) | H22: =IF(D22="",0,1/COUNTIF($D$2:$D$3451,D22)) -> 0 | I22: =IFERROR(INDEX('NCO-2015 scores'!$C$2:$C$131,MATCH(E22,'NCO-2015 scores'!$A$2:$A$131,0)),0) -> 0.4975 | J22: =IF(ISNUMBER(MATCH(E22,'NCO-2015 scores'!$A$2:$A$131,0)),IF(ISNUMBER(INDEX('NCO-2015 scores'!$C$2:$C$131,MATCH(E22,'NCO-2015 scores'!$A$2:$A$131,0))),1,0),0) -> 1
A23: 22 | B23: Product Brand Manager (Automotive) | C23: 2431.0201 | E23: =LEFT(C23,3) -> 243 | F23: =IF(D23="","",LEFT(D23,3)) | G23: =IF(F23="","",IF(E23=F23,"Yes","No")) | H23: =IF(D23="",0,1/COUNTIF($D$2:$D$3451,D23)) -> 0 | I23: =IFERROR(INDEX('NCO-2015 scores'!$C$2:$C$131,MATCH(E23,'NCO-2015 scores'!$A$2:$A$131,0)),0) -> 0.4975 | J23: =IF(ISNUMBER(MATCH(E23,'NCO-2015 scores'!$A$2:$A$131,0)),IF(ISNUMBER(INDEX('NCO-2015 scores'!$C$2:$C$131,MATCH(E23,'NCO-2015 scores'!$A$2:$A$131,0))),1,0),0) -> 1
A24: 23 | B24: Account Executive (Advertising Agency) | C24: 2431.0202 | E24: =LEFT(C24,3) -> 243 | F24: =IF(D24="","",LEFT(D24,3)) | G24: =IF(F24="","",IF(E24=F24,"Yes","No")) | H24: =IF(D24="",0,1/COUNTIF($D$2:$D$3451,D24)) -> 0 | I24: =IFERROR(INDEX('NCO-2015 scores'!$C$2:$C$131,MATCH(E24,'NCO-2015 scores'!$A$2:$A$131,0)),0) -> 0.4975 | J24: =IF(ISNUMBER(MATCH(E24,'NCO-2015 scores'!$A$2:$A$131,0)),IF(ISNUMBER(INDEX('NCO-2015 scores'!$C$2:$C$131,MATCH(E24,'NCO-2015 scores'!$A$2:$A$131,0))),1,0),0) -> 1
A25: 24 | B25: Product Executive | C25: 2431.0601 | E25: =LEFT(C25,3) -> 243 | F25: =IF(D25="","",LEFT(D25,3)) | G25: =IF(F25="","",IF(E25=F25,"Yes","No")) | H25: =IF(D25="",0,1/COUNTIF($D$2:$D$3451,D25)) -> 0 | I25: =IFERROR(INDEX('NCO-2015 scores'!$C$2:$C$131,MATCH(E25,'NCO-2015 scores'!$A$2:$A$131,0)),0) -> 0.4975 | J25: =IF(ISNUMBER(MATCH(E25,'NCO-2015 scores'!$A$2:$A$131,0)),IF(ISNUMBER(INDEX('NCO-2015 scores'!$C$2:$C$131,MATCH(E25,'NCO-2015 scores'!$A$2:$A$131,0))),1,0),0) -> 1
A26: 25 | B26: Sales Executive (Media Org) | C26: 2431.0651 | E26: =LEFT(C26,3) -> 243 | F26: =IF(D26="","",LEFT(D26,3)) | G26: =IF(F26="","",IF(E26=F26,"Yes","No")) | H26: =IF(D26="",0,1/COUNTIF($D$2:$D$3451,D26)) -> 0 | I26: =IFERROR(INDEX('NCO-2015 scores'!$C$2:$C$131,MATCH(E26,'NCO-2015 scores'!$A$2:$A$131,0)),0) -> 0.4975 | J26: =IF(ISNUMBER(MATCH(E26,'NCO-2015 scores'!$A$2:$A$131,0)),IF(ISNUMBER(INDEX('NCO-2015 scores'!$C$2:$C$131,MATCH(E26,'NCO-2015 scores'!$A$2:$A$131,0))),1,0),0) -> 1
A27: 26 | B27: Traffic Co-Ordinator | C27: 2431.0671 | E27: =LEFT(C27,3) -> 243 | F27: =IF(D27="","",LEFT(D27,3)) | G27: =IF(F27="","",IF(E27=F27,"Yes","No")) | H27: =IF(D27="",0,1/COUNTIF($D$2:$D$3451,D27)) -> 0 | I27: =IFERROR(INDEX('NCO-2015 scores'!$C$2:$C$131,MATCH(E27,'NCO-2015 scores'!$A$2:$A$131,0)),0) -> 0.4975 | J27: =IF(ISNUMBER(MATCH(E27,'NCO-2015 scores'!$A$2:$A$131,0)),IF(ISNUMBER(INDEX('NCO-2015 scores'!$C$2:$C$131,MATCH(E27,'NCO-2015 scores'!$A$2:$A$131,0))),1,0),0) -> 1
A28: 27 | B28: Creative Writer | C28: 2431.0700 | D28: 2451.52 | E28: =LEFT(C28,3) -> 243 | F28: =IF(D28="","",LEFT(D28,3)) -> 245 | G28: =IF(F28="","",IF(E28=F28,"Yes","No")) -> No | H28: =IF(D28="",0,1/COUNTIF($D$2:$D$3451,D28)) -> 1 | I28: =IFERROR(INDEX('NCO-2015 scores'!$C$2:$C$131,MATCH(E28,'NCO-2015 scores'!$A$2:$A$131,0)),0) -> 0.4975 | J28: =IF(ISNUMBER(MATCH(E28,'NCO-2015 scores'!$A$2:$A$131,0)),IF(ISNUMBER(INDEX('NCO-2015 scores'!$C$2:$C$131,MATCH(E28,'NCO-2015 scores'!$A$2:$A$131,0))),1,0),0) -> 1
A29: 28 | B29: Propagandist | C29: 2431.0800 | D29: 3411.30 | E29: =LEFT(C29,3) -> 243 | F29: =IF(D29="","",LEFT(D29,3)) -> 341 | G29: =IF(F29="","",IF(E29=F29,"Yes","No")) -> No | H29: =IF(D29="",0,1/COUNTIF($D$2:$D$3451,D29)) -> 1 | I29: =IFERROR(INDEX('NCO-2015 scores'!$C$2:$C$131,MATCH(E29,'NCO-2015 scores'!$A$2:$A$131,0)),0) -> 0.4975 | J29: =IF(ISNUMBER(MATCH(E29,'NCO-2015 scores'!$A$2:$A$131,0)),IF(ISNUMBER(INDEX('NCO-2015 scores'!$C$2:$C$131,MATCH(E29,'NCO-2015 scores'!$A$2:$A$131,0))),1,0),0) -> 1
A30: 29 | B30: Advertising and Marketing Professionals, Other | C30: 2431.9900 | E30: =LEFT(C30,3) -> 243 | F30: =IF(D30="","",LEFT(D30,3)) | G30: =IF(F30="","",IF(E30=F30,"Yes","No")) | H30: =IF(D30="",0,1/COUNTIF($D$2:$D$3451,D30)) -> 0 | I30: =IFERROR(INDEX('NCO-2015 scores'!$C$2:$C$131,MATCH(E30,'NCO-2015 scores'!$A$2:$A$131,0)),0) -> 0.4975 | J30: =IF(ISNUMBER(MATCH(E30,'NCO-2015 scores'!$A$2:$A$131,0)),IF(ISNUMBER(INDEX('NCO-2015 scores'!$C$2:$C$131,MATCH(E30,'NCO-2015 scores'!$A$2:$A$131,0))),1,0),0) -> 1
A31: 30 | B31: Regional Service Process Manager | C31: 2431.0102 | E31: =LEFT(C31,3) -> 243 | F31: =IF(D31="","",LEFT(D31,3)) | G31: =IF(F31="","",IF(E31=F31,"Yes","No")) | H31: =IF(D31="",0,1/COUNTIF($D$2:$D$3451,D31)) -> 0 | I31: =IFERROR(INDEX('NCO-2015 scores'!$C$2:$C$131,MATCH(E31,'NCO-2015 scores'!$A$2:$A$131,0)),0) -> 0.4975 | J31: =IF(ISNUMBER(MATCH(E31,'NCO-2015 scores'!$A$2:$A$131,0)),IF(ISNUMBER(INDEX('NCO-2015 scores'!$C$2:$C$131,MATCH(E31,'NCO-2015 scores'!$A$2:$A$131,0))),1,0),0) -> 1
A32: 31 | B32: Market Research Associate – Sales & Marketing/Business Development | C32: 2431.0501 | E32: =LEFT(C32,3) -> 243 | F32: =IF(D32="","",LEFT(D32,3)) | G32: =IF(F32="","",IF(E32=F32,"Yes","No")) | H32: =IF(D32="",0,1/COUNTIF($D$2:$D$3451,D32)) -> 0 | I32: =IFERROR(INDEX('NCO-2015 scores'!$C$2:$C$131,MATCH(E32,'NCO-2015 scores'!$A$2:$A$131,0)),0) -> 0.4975 | J32: =IF(ISNUMBER(MATCH(E32,'NCO-2015 scores'!$A$2:$A$131,0)),IF(ISNUMBER(INDEX('NCO-2015 scores'!$C$2:$C$131,MATCH(E32,'NCO-2015 scores'!$A$2:$A$131,0))),1,0),0) -> 1
A33: 32 | B33: Management Trainee – Sales & Marketing/Business Development | C33: 2431.0502 | E33: =LEFT(C33,3) -> 243 | F33: =IF(D33="","",LEFT(D33,3)) | G33: =IF(F33="","",IF(E33=F33,"Yes","No")) | H33: =IF(D33="",0,1/COUNTIF($D$2:$D$3451,D33)) -> 0 | I33: =IFERROR(INDEX('NCO-2015 scores'!$C$2:$C$131,MATCH(E33,'NCO-2015 scores'!$A$2:$A$131,0)),0) -> 0.4975 | J33: =IF(ISNUMBER(MATCH(E33,'NCO-2015 scores'!$A$2:$A$131,0)),IF(ISNUMBER(INDEX('NCO-2015 scores'!$C$2:$C$131,MATCH(E33,'NCO-2015 scores'!$A$2:$A$131,0))),1,0),0) -> 1
